<?xml version="1.0" ?>
<!-- =================================================================================== -->
<!-- |    This document was autogenerated by xacro from scout_mini.xacro               | -->
<!-- |    EDITING THIS FILE BY HAND IS NOT RECOMMENDED                                 | -->
<!-- =================================================================================== -->
<robot name="scout_mini">
  <!-- Base link -->
  <link name="base_link">
    <visual>
      <origin rpy="0 0 0" xyz="0.015 0.0231316650320557 0"/>
      <geometry>
        <mesh filename="package://scout_description/meshes/scout_mini_base_link.STL"/>
      </geometry>
    </visual>
    <collision>
      <origin rpy="0 0 0" xyz="0.015 0.0231316650320557 0"/>
      <geometry>
        <mesh filename="package://scout_description/meshes/scout_mini_base_link.STL"/>
      </geometry>
    </collision>
  </link>
  <link name="inertial_link">
    <inertial>
      <mass value="132.3898489950015"/>
      <inertia ixx="0.6022" ixy="-0.02364" ixz="-0.1197" iyy="1.7386" iyz="-0.001544" izz="2.0296"/>
       --&gt;
            
      <origin xyz="0.015 0.0231316650320557 0"/>
      <inertia ixx="0.185196122711036" ixy="4.30144213829512E-08" ixz="5.81037523686401E-08" iyy="0.364893736238929" iyz="-0.000386720198091934" izz="0.223868521722778"/>
    </inertial>
  </link>
  <joint name="inertial_joint" type="fixed">
    <origin rpy="0 0 0" xyz="0 0 0"/>
    <parent link="base_link"/>
    <child link="inertial_link"/>
  </joint>
  <!-- For testing, hang the robot up in the air -->
  <!-- <link name="world" />
    <joint name="world_to_base_link=" type="fixed">
        <origin xyz="0 0 0.5" rpy="0 0 0" />
        <parent link="world"/>
        <child link="base_link"/>
    </joint> -->
  <link name="rear_right_wheel_link">
    <!--<inertial>
                <mass value="3" />
                <origin
                        xyz="0.162297526351145 -0.159063056237197 -0.159999952657767"
                        rpy="0 0 0" />
                        <inertia ixx="0.7171" ixy="0" ixz="0" iyy="0.1361" iyz="0" izz="0.7171" />
                   </inertial>
            <visual>
                <origin xyz="0 0 0" rpy="0 0 0" />
                <geometry>
                    <mesh filename="file://$(find scout_description)/meshes/wheel.dae" />
                </geometry>
            </visual>-->
    <inertial>
      <mass value="3"/>
      <origin xyz="0 0 0"/>
      <inertia ixx="0.7171" ixy="0" ixz="0" iyy="0.7171" iyz="0" izz="0.1361"/>
      <!--<inertia ixx="0" ixy="0" ixz="0" iyy="0" iyz="0" izz="0" />-->
    </inertial>
    <visual>
      <origin rpy="0 0 0" xyz="0 0 0"/>
      <geometry>
        <mesh filename="file:///home/dongkuo/ros2_pkgs_src/scout_ros2_driver/build_ws/install/scout_description/share/scout_description/meshes/wheel.dae"/>
      </geometry>
    </visual>
    <collision>
      <origin rpy="0 0 0" xyz="0 0 0"/>
      <geometry>
        <mesh filename="file:///home/dongkuo/ros2_pkgs_src/scout_ros2_driver/build_ws/install/scout_description/share/scout_description/meshes/wheel.dae"/>
      </geometry>
    </collision>
  </link>
  <joint name="rear_right_wheel" type="continuous">
    <!--<origin
                  xyz="0.14547 0.20835 -0.07424"
                  rpy="0 1.57 0" />-->
    <parent link="base_link"/>
    <child link="rear_right_wheel_link"/>
    <origin rpy="0 1.57 0" xyz="0.1566278 -0.2281768 -0.077"/>
    <axis rpy="0 0 0" xyz="0 0 1"/>
  </joint>
  <link name="front_right_wheel_link">
    <!--<inertial>
            <mass value="3" />
                <origin
                        xyz="0.162297526351148 0.159063056237198 -0.160000047342231"
                        rpy="0 0 0" />
                        <inertia ixx="0.7171" ixy="0" ixz="0" iyy="0.1361" iyz="0" izz="0.7171" />
            </inertial>
            <visual>
                <origin xyz="0 0 0" rpy="0 0 0" />
                <geometry>
                    <mesh filename="file://$(find scout_description)/meshes/wheel.dae" />
                </geometry>
            </visual>-->
    <inertial>
      <mass value="3"/>
      <origin xyz="0 0 0"/>
      <inertia ixx="0.7171" ixy="0" ixz="0" iyy="0.7171" iyz="0" izz="0.1361"/>
      <!--<inertia ixx="0" ixy="0" ixz="0" iyy="0" iyz="0" izz="0" />-->
    </inertial>
    <visual>
      <origin rpy="0 0 0" xyz="0 0 0"/>
      <geometry>
        <mesh filename="file:///home/dongkuo/ros2_pkgs_src/scout_ros2_driver/build_ws/install/scout_description/share/scout_description/meshes/wheel.dae"/>
      </geometry>
    </visual>
    <collision>
      <origin rpy="0 0 0" xyz="0 0 0"/>
      <geometry>
        <mesh filename="file:///home/dongkuo/ros2_pkgs_src/scout_ros2_driver/build_ws/install/scout_description/share/scout_description/meshes/wheel.dae"/>
      </geometry>
    </collision>
  </link>
  <joint name="front_right_wheel" type="continuous">
    <!--<origin
                  xyz="-0.17453 0.20835 -0.07424"
                  rpy="0 -1.57 0" />-->
    <parent link="base_link"/>
    <child link="front_right_wheel_link"/>
    <origin rpy="0 1.57 0" xyz="0.1566278 0.2281768 -0.077"/>
    <axis rpy="0 0 0" xyz="0 0 1"/>
  </joint>
  <link name="front_left_wheel_link">
    <!--<inertial>
            <mass value="3" />
                <origin
                        xyz="-0.235088020493741 -0.0575697183039213 -0.16000004734223"
                        rpy="0 0 0" />
                        <inertia ixx="0.7171" ixy="0" ixz="0" iyy="0.1361" iyz="0" izz="0.7171" />
            </inertial>
            <visual>
                <origin xyz="0 0 0" rpy="0 0 0" />
                <geometry>
                    <mesh filename="file://$(find scout_description)/meshes/wheel.dae" />
                </geometry>
            </visual>-->
    <inertial>
      <mass value="3"/>
      <origin xyz="0 0 0"/>
      <inertia ixx="0.7171" ixy="0" ixz="0" iyy="0.7171" iyz="0" izz="0.1361"/>
      <!--<inertia ixx="0" ixy="0" ixz="0" iyy="0" iyz="0" izz="0" />-->
    </inertial>
    <visual>
      <origin rpy="0 0 0" xyz="0 0 0"/>
      <geometry>
        <mesh filename="file:///home/dongkuo/ros2_pkgs_src/scout_ros2_driver/build_ws/install/scout_description/share/scout_description/meshes/wheel.dae"/>
      </geometry>
    </visual>
    <collision>
      <origin rpy="0 0 0" xyz="0 0 0"/>
      <geometry>
        <mesh filename="file:///home/dongkuo/ros2_pkgs_src/scout_ros2_driver/build_ws/install/scout_description/share/scout_description/meshes/wheel.dae"/>
      </geometry>
    </collision>
  </link>
  <joint name="front_left_wheel" type="continuous">
    <!--<origin
                  xyz="-0.17453 -0.24424 -0.07424"
                  rpy="0 -1.57 0" />-->
    <parent link="base_link"/>
    <child link="front_left_wheel_link"/>
    <origin rpy="0 -1.57 0" xyz="-0.1566278 0.2281768 -0.077"/>
    <axis rpy="0 0 0" xyz="0 0 -1"/>
  </joint>
  <link name="rear_left_wheel_link">
    <!--<inertial>
        <mass value="3" />
            <origin
                    xyz="0.235244832119832 -0.0585653794466942 -0.206994929144493"
                    rpy="0 0 0" />
                    <inertia ixx="0.7171" ixy="0" ixz="0" iyy="0.1361" iyz="0" izz="0.7171" />
        </inertial>
        <visual>
            <origin xyz="0 0 0" rpy="0 0 0" />
            <geometry>
                <mesh filename="file://$(find scout_description)/meshes/wheel.dae" />
            </geometry>
        </visual>-->
    <inertial>
      <mass value="3"/>
      <origin xyz="0 0 0"/>
      <inertia ixx="0.7171" ixy="0" ixz="0" iyy="0.7171" iyz="0" izz="0.1361"/>
      <!--<inertia ixx="0" ixy="0" ixz="0" iyy="0" iyz="0" izz="0" />-->
    </inertial>
    <visual>
      <origin rpy="0 0 0" xyz="0 0 0"/>
      <geometry>
        <mesh filename="file:///home/dongkuo/ros2_pkgs_src/scout_ros2_driver/build_ws/install/scout_description/share/scout_description/meshes/wheel.dae"/>
      </geometry>
    </visual>
    <collision>
      <origin rpy="0 0 0" xyz="0 0 0"/>
      <geometry>
        <mesh filename="file:///home/dongkuo/ros2_pkgs_src/scout_ros2_driver/build_ws/install/scout_description/share/scout_description/meshes/wheel.dae"/>
      </geometry>
    </collision>
  </link>
  <joint name="rear_left_wheel" type="continuous">
    <!--<origin
                  xyz="0.19247 -0.24486 -0.073441"
                  rpy="-0 1.57 0" />-->
    <parent link="base_link"/>
    <child link="rear_left_wheel_link"/>
    <origin rpy="0 -1.57 0" xyz="-0.1566278 -0.2281768 -0.077"/>
    <axis rpy="0 0 0" xyz="0 0 -1"/>
  </joint>
  <!-- This file is a placeholder which is included by default from
       husky.urdf.xacro. If a robot is being customized and requires
       additional URDF, set the HUSKY_URDF_EXTRAS environment variable
       to the full path of the file you would like included. -->
  <!-- <xacro:include filename="$(find scout_description)/urdf/scout_wheel.gazebo" /> -->
  <!-- Additional definitions for simulation -->
  <!-- <gazebo reference="base_link">
        <material>Gazebo/Grey</material>
    </gazebo> -->
  <!-- Actuator configurations 
    <xacro:scout_wheel_transmission wheel_prefix="front_right" />
    <xacro:scout_wheel_transmission wheel_prefix="front_left" />
    <xacro:scout_wheel_transmission wheel_prefix="rear_left" />
    <xacro:scout_wheel_transmission wheel_prefix="rear_right" />-->
  <!-- Controller configurations -->
  <!-- <gazebo>
        <plugin name="gazebo_ros_control" filename="libgazebo_ros_control.so">
            <robotNamespace>$(arg robot_namespace)</robotNamespace>
        </plugin>
    </gazebo> -->
  <!-- kp spring constant, kd damping constant -->
  <gazebo>
    <mu1 value="1.0"/>
    <mu2 value="0.9"/>
    <kp value="10000000.0"/>
    <kd value="1.0"/>
    <fdir1 value="1 0 0"/>
    <minDepth value="0.001"/>
    <maxContacts value="64"/>
  </gazebo>
  <gazebo reference="base_link">
    <mu1>0.2</mu1>
    <mu2>0.2</mu2>
  </gazebo>
  <gazebo reference="front_right_wheel_link">
    <mu1>0.2</mu1>
    <mu2>0.2</mu2>
  </gazebo>
  <gazebo reference="front_left_wheel_link">
    <mu1>0.2</mu1>
    <mu2>0.2</mu2>
  </gazebo>
  <gazebo reference="rear_left_wheel_link">
    <mu1>0.2</mu1>
    <mu2>0.2</mu2>
  </gazebo>
  <gazebo reference="rear_right_wheel_link">
    <mu1>0.2</mu1>
    <mu2>0.2</mu2>
  </gazebo>
  <!-- <gazebo>
        <plugin name="skid_steer_drive_controller" filename="libgazebo_ros_skid_steer_drive.so">
            <updateRate>100.0</updateRate>
            <robotNamespace></robotNamespace>
            <leftFrontJoint>front_left_wheel</leftFrontJoint>
            <rightFrontJoint>front_right_wheel</rightFrontJoint>
            <leftRearJoint>rear_left_wheel</leftRearJoint>
            <rightRearJoint>rear_right_wheel</rightRearJoint>
            <wheelSeparation>4</wheelSeparation>
            <wheelDiameter>0.32918</wheelDiameter>
            <robotBaseFrame>base_link</robotBaseFrame>
            <torque>1000</torque>
            <commandTopic>cmd_vel</commandTopic>
            <broadcastTF>true</broadcastTF>
            <odometryTopic>odom</odometryTopic>
            <odometryFrame>odom</odometryFrame>
            <covariance_x>0.000100</covariance_x>
            <covariance_y>0.000100</covariance_y>
            <covariance_yaw>0.010000</covariance_yaw>
        </plugin>
    </gazebo> -->
  <!-- Use gazebo_ros_joint_state_publisher instead of publishWheelJointState -->
  <!-- <gazebo>
    <plugin name="joint_states" filename="libgazebo_ros_joint_state_publisher.so">
        <joint_name>front_left_wheel</joint_name>
        <joint_name>front_right_wheel</joint_name>
        <joint_name>rear_left_wheel</joint_name>
        <joint_name>rear_right_wheel</joint_name>
    </plugin>


    <plugin name='diff_drive' filename='libgazebo_ros_diff_drive.so'>
        <update_rate>500</update_rate>
        <left_joint>front_left_wheel</left_joint>
        <right_joint>front_right_wheel</right_joint>
        <left_joint>rear_left_wheel</left_joint>
        <right_joint>rear_right_wheel</right_joint>

        <wheel_separation>4</wheel_separation>
        <wheel_diameter>0.32918</wheel_diameter>
        <odometry_frame>odom</odometry_frame>

        <max_wheel_torque>20</max_wheel_torque>
        <max_acceleration>1.0</max_acceleration>

        <publish_odom>true</publish_odom>
        <publish_odom_tf>true</publish_odom_tf>
        <publish_wheel_tf>true</publish_wheel_tf>
        <odometry_frame>odom</odometry_frame>
        <robot_base_frame>base_footprint</robot_base_frame>

    </plugin>
    </gazebo> -->
  <gazebo>
    <plugin filename="libgazebo_ros_diff_drive.so" name="diff_drive">
      <ros>
        <namespace>/</namespace>
        <remapping>cmd_vel:=cmd_vel</remapping>
        <remapping>odom:=odom</remapping>
      </ros>
      <update_rate>30</update_rate>
      <num_wheel_pairs>2</num_wheel_pairs>
      <left_joint>front_left_wheel</left_joint>
      <right_joint>front_right_wheel</right_joint>
      <left_joint>rear_left_wheel</left_joint>
      <right_joint>rear_right_wheel</right_joint>
      <wheel_separation>0.451</wheel_separation>
      <wheel_separation>0.451</wheel_separation>
      <wheel_diameter>0.08</wheel_diameter>
      <wheel_diameter>0.08</wheel_diameter>
      <max_wheel_torque>1000</max_wheel_torque>
      <max_wheel_acceleration>1.0</max_wheel_acceleration>
      <publish_odom>true</publish_odom>
      <publish_odom_tf>true</publish_odom_tf>
      <publish_wheel_tf>true</publish_wheel_tf>
      <odometry_frame>odom</odometry_frame>
      <robot_base_frame>base_link</robot_base_frame>
    </plugin>
  </gazebo>
  <!-- ========================================================= -->
  <!--                ADDITIONAL COORDINATE FRAMES               -->
  <!-- ========================================================= -->
  <!-- 1. base_footprint (ground projection of base_link) -->
  <link name="base_footprint"/>
  <joint name="base_footprint_joint" type="fixed">
    <origin rpy="0 0 0" xyz="0 0 0.11854"/>
    <parent link="base_footprint"/>
    <child link="base_link"/>
  </joint>
  <!-- 2. imu_link (IMU reference frame) -->
  <link name="imu_link">
    <visual>
      <origin rpy="0 0 0" xyz="0 0 0"/>
      <geometry>
        <sphere radius="0.02"/>
      </geometry>
      <material name="IMU_Cyan">
        <color rgba="0 1 1 1"/>
      </material>
    </visual>
  </link>
  <joint name="imu_joint" type="fixed">
    <origin rpy="0 0 0" xyz="0 0 0.12393"/>
    <parent link="base_link"/>
    <child link="imu_link"/>
  </joint>
  <!-- 3. gps_link (antenna reference) -->
  <link name="gps">
    <visual>
      <origin rpy="0 0 0" xyz="0 0 0"/>
      <geometry>
        <cylinder length="0.05" radius="0.015"/>
      </geometry>
      <material name="GPS_Yellow">
        <color rgba="1 1 0 1"/>
      </material>
    </visual>
  </link>
  <joint name="gps_joint" type="fixed">
    <origin rpy="0 0 0" xyz="0 0 0.12393"/>
    <parent link="base_link"/>
    <child link="gps"/>
  </joint>
  <!-- 4. lidar_link -->
  <link name="livox_frame">
    <visual>
      <origin rpy="0 0 0" xyz="0 0 0"/>
      <geometry>
        <cylinder length="0.05" radius="0.03"/>
      </geometry>
      <material name="LIDAR_Grey">
        <color rgba="0.6 0.6 0.6 1"/>
      </material>
    </visual>
  </link>
  <joint name="lidar_joint" type="fixed">
    <!-- 前 0.55851 m -> +X；上 0.26763 m -> +Z；pitch=+15°=0.261799 rad -->
    <origin rpy="0.0 0.261799 0.0" xyz="0.55851 0.0 0.26763"/>
    <parent link="base_link"/>
    <child link="livox_frame"/>
  </joint>
</robot>
